There were OSErrors
There were SystemErrors
  + Exception Group Traceback (most recent call last):
  |   File "C:\Users\40843\test1.py", line 18, in <module>
  |     f()
  |   File "C:\Users\40843\test1.py", line 2, in f
  |     raise ExceptionGroup(
  | ExceptionGroup: group1 (1 sub-exception)
  +-+---------------- 1 ----------------
    | ExceptionGroup: group2 (1 sub-exception)
    +-+---------------- 1 ----------------
      | RecursionError: 4
      +------------------------------------
